<?xml version="1.0"?>
<robot name="object">
  <link name="base_link"> <!-- required name-->
    <inertial>
      <origin xyz="0 0 0" /> 
      <mass value="1.0" />
      <inertia  ixx="1.0" ixy="0.0"  ixz="0.0"  iyy="1.0"  iyz="0.0"  izz="1.0" />
    </inertial>
    <visual>
      <origin xyz="0 0 0"/>
      <geometry>
        <sphere radius="0.2"/>
      </geometry>
      <material name="gray">
        <color rgba="0.3 0.3 0.3 1"/>
      </material>
    </visual>
    <collision>
      <origin xyz="0 0 0"/>
      <geometry>
        <sphere radius="0.2"/>
      </geometry>
    </collision>
  </link>

  <joint name="j_bounding_sphere" type="fixed">
    <parent link="base_link"/>
    <child link="l_bounding_sphere"/>
    <origin xyz="0 0 0"/>
  </joint>

  <link name="l_bounding_sphere">
    <visual>
      <origin xyz="0 0 0"/>
      <geometry>
        <sphere radius="0.4"/>
      </geometry>
      <material name="green">
        <color rgba="0 0.8 0.1 0.1"/>
      </material>
    </visual>
    <collision>
      <origin xyz="0 0 0"/>
      <geometry>
        <sphere radius="0.4"/>
      </geometry>
     </collision>
   </link>
   
   <joint name="j_rigid_leg" type="fixed">
    <parent link="base_link"/>
    <child link="l_rigid_leg"/>
    <origin xyz="0 0 -0.25"/>
  </joint>

  <link name="l_rigid_leg">
    <visual>
      <origin xyz="0 0 0"/>
      <geometry>
        <cylinder length="0.1" radius="0.02"/>
      </geometry>
      <material name="gray"/>
    </visual>
    <collision>
      <origin xyz="0 0 0"/>
      <geometry>
        <cylinder length="0.1" radius="0.02"/>
      </geometry>
     </collision>
   </link>

  <joint name="j_mobile_leg" type="prismatic">
    <parent link="base_link"/>
    <child link="l_mobile_leg"/>
    <origin xyz="0 0 -0.25"/>
    <axis xyz="0 0 1"/>
    <limit lower="-0.1" upper="0" effort="1.0" velocity="1.0"/>
  </joint>

  <link name="l_mobile_leg">
    <visual>
      <origin xyz="0 0 0"/>
      <geometry>
        <cylinder length="0.101" radius="0.018"/>
      </geometry>
      <material name="red">
        <color rgba="1 0 0 1"/>
      </material>
    </visual>
    <collision>
      <origin xyz="0 0 0"/>
      <geometry>
        <cylinder length="0.101" radius="0.018"/>
      </geometry>
     </collision>
   </link>
</robot>
